Loading agent under protect_vs_invade
Successfully restored tracker policy and optimizer.
[34m[1mwandb[0m: [32m[41mERROR[0m artifact 'run_1_target_checkpoint:latest' not found in 'huhugiao-bit/protect_vs_invade'
Traceback (most recent call last):
  File "/home/ace/miniconda3/envs/lnenv/lib/python3.8/site-packages/wandb/apis/normalize.py", line 25, in wrapper
    return func(*args, **kwargs)
  File "/home/ace/miniconda3/envs/lnenv/lib/python3.8/site-packages/wandb/apis/public/api.py", line 1286, in _artifact
    artifact = wandb.Artifact._from_name(
  File "/home/ace/miniconda3/envs/lnenv/lib/python3.8/site-packages/wandb/sdk/artifacts/artifact.py", line 294, in _from_name
    raise ValueError(f"artifact '{name}' not found in '{entity}/{project}'")
ValueError: artifact 'run_1_target_checkpoint:latest' not found in 'huhugiao-bit/protect_vs_invade'

During handling of the above exception, another exception occurred:

Traceback (most recent call last):
  File "/home/ace/miniconda3/envs/lnenv/lib/python3.8/site-packages/gym/envs/user/protect/main.py", line 211, in <module>
    alt_train()
  File "/home/ace/miniconda3/envs/lnenv/lib/python3.8/site-packages/gym/envs/user/protect/main.py", line 203, in alt_train
    train(active_policy=active_policy)
  File "/home/ace/miniconda3/envs/lnenv/lib/python3.8/site-packages/gym/envs/user/protect/main.py", line 147, in train
    result = OnpolicyTrainer(
  File "/home/ace/miniconda3/envs/lnenv/lib/python3.8/site-packages/tianshou/trainer/base.py", line 440, in run
    deque(self, maxlen=0)  # feed the entire iterator into a zero-length deque
  File "/home/ace/miniconda3/envs/lnenv/lib/python3.8/site-packages/tianshou/trainer/base.py", line 252, in __iter__
    self.reset()
  File "/home/ace/miniconda3/envs/lnenv/lib/python3.8/site-packages/tianshou/trainer/base.py", line 221, in reset
    self.logger.restore_data()
  File "/home/ace/miniconda3/envs/lnenv/lib/python3.8/site-packages/tianshou/utils/logger/wandb.py", line 128, in restore_data
    checkpoint_artifact = self.wandb_run.use_artifact(    # type: ignore
  File "/home/ace/miniconda3/envs/lnenv/lib/python3.8/site-packages/wandb/sdk/wandb_run.py", line 401, in wrapper_fn
    return func(self, *args, **kwargs)
  File "/home/ace/miniconda3/envs/lnenv/lib/python3.8/site-packages/wandb/sdk/wandb_run.py", line 391, in wrapper
    return func(self, *args, **kwargs)
  File "/home/ace/miniconda3/envs/lnenv/lib/python3.8/site-packages/wandb/sdk/wandb_run.py", line 2999, in use_artifact
    artifact = public_api._artifact(type=type, name=name)
  File "/home/ace/miniconda3/envs/lnenv/lib/python3.8/site-packages/wandb/apis/normalize.py", line 79, in wrapper
    raise CommError(message, err).with_traceback(sys.exc_info()[2])
  File "/home/ace/miniconda3/envs/lnenv/lib/python3.8/site-packages/wandb/apis/normalize.py", line 25, in wrapper
    return func(*args, **kwargs)
  File "/home/ace/miniconda3/envs/lnenv/lib/python3.8/site-packages/wandb/apis/public/api.py", line 1286, in _artifact
    artifact = wandb.Artifact._from_name(
  File "/home/ace/miniconda3/envs/lnenv/lib/python3.8/site-packages/wandb/sdk/artifacts/artifact.py", line 294, in _from_name
    raise ValueError(f"artifact '{name}' not found in '{entity}/{project}'")
wandb.errors.errors.CommError: artifact 'run_1_target_checkpoint:latest' not found in 'huhugiao-bit/protect_vs_invade'
