2025-04-24 21:12:19,252 INFO    MainThread:17184 [wandb_setup.py:_flush():67] Current SDK version is 0.19.8
2025-04-24 21:12:19,253 INFO    MainThread:17184 [wandb_setup.py:_flush():67] Configure stats pid to 17184
2025-04-24 21:12:19,253 INFO    MainThread:17184 [wandb_setup.py:_flush():67] Loading settings from /home/ace/.config/wandb/settings
2025-04-24 21:12:19,253 INFO    MainThread:17184 [wandb_setup.py:_flush():67] Loading settings from /home/ace/miniconda3/envs/lnenv/lib/python3.8/site-packages/gym/envs/user/protect/wandb/settings
2025-04-24 21:12:19,253 INFO    MainThread:17184 [wandb_setup.py:_flush():67] Loading settings from environment variables
2025-04-24 21:12:19,253 INFO    MainThread:17184 [wandb_init.py:setup_run_log_directory():647] Logging user logs to /home/ace/miniconda3/envs/lnenv/lib/python3.8/site-packages/gym/envs/user/protect/wandb/run-20250424_211219-2_tracker/logs/debug.log
2025-04-24 21:12:19,253 INFO    MainThread:17184 [wandb_init.py:setup_run_log_directory():648] Logging internal logs to /home/ace/miniconda3/envs/lnenv/lib/python3.8/site-packages/gym/envs/user/protect/wandb/run-20250424_211219-2_tracker/logs/debug-internal.log
2025-04-24 21:12:19,254 INFO    MainThread:17184 [wandb_init.py:init():761] calling init triggers
2025-04-24 21:12:19,254 INFO    MainThread:17184 [wandb_init.py:init():766] wandb.init called with sweep_config: {}
config: {'_wandb': {}}
2025-04-24 21:12:19,254 INFO    MainThread:17184 [wandb_init.py:init():784] starting backend
2025-04-24 21:12:19,254 INFO    MainThread:17184 [wandb_init.py:init():788] sending inform_init request
2025-04-24 21:12:19,273 INFO    MainThread:17184 [backend.py:_multiprocessing_setup():101] multiprocessing start_methods=fork,spawn,forkserver, using: spawn
2025-04-24 21:12:19,273 INFO    MainThread:17184 [wandb_init.py:init():798] backend started and connected
2025-04-24 21:12:19,275 INFO    MainThread:17184 [wandb_init.py:init():891] updated telemetry
2025-04-24 21:12:19,289 INFO    MainThread:17184 [wandb_init.py:init():915] communicating run to backend with 90.0 second timeout
2025-04-24 21:13:49,291 ERROR   MainThread:17184 [wandb_init.py:init():1478] error in wandb.init()
Traceback (most recent call last):
  File "/home/ace/miniconda3/envs/lnenv/lib/python3.8/site-packages/wandb/sdk/mailbox/response_handle.py", line 109, in wait_async
    await asyncio.wait_for(evt.wait(), timeout=timeout)
  File "/home/ace/miniconda3/envs/lnenv/lib/python3.8/asyncio/tasks.py", line 501, in wait_for
    raise exceptions.TimeoutError()
asyncio.exceptions.TimeoutError

The above exception was the direct cause of the following exception:

Traceback (most recent call last):
  File "/home/ace/miniconda3/envs/lnenv/lib/python3.8/site-packages/wandb/sdk/wandb_init.py", line 941, in init
    result = wait_with_progress(
  File "/home/ace/miniconda3/envs/lnenv/lib/python3.8/site-packages/wandb/sdk/mailbox/wait_with_progress.py", line 24, in wait_with_progress
    return wait_all_with_progress(
  File "/home/ace/miniconda3/envs/lnenv/lib/python3.8/site-packages/wandb/sdk/mailbox/wait_with_progress.py", line 87, in wait_all_with_progress
    return asyncio_compat.run(progress_loop_with_timeout)
  File "/home/ace/miniconda3/envs/lnenv/lib/python3.8/site-packages/wandb/sdk/lib/asyncio_compat.py", line 30, in run
    return future.result()
  File "/home/ace/miniconda3/envs/lnenv/lib/python3.8/concurrent/futures/_base.py", line 444, in result
    return self.__get_result()
  File "/home/ace/miniconda3/envs/lnenv/lib/python3.8/concurrent/futures/_base.py", line 389, in __get_result
    raise self._exception
  File "/home/ace/miniconda3/envs/lnenv/lib/python3.8/concurrent/futures/thread.py", line 57, in run
    result = self.fn(*self.args, **self.kwargs)
  File "/home/ace/miniconda3/envs/lnenv/lib/python3.8/site-packages/wandb/sdk/lib/asyncio_compat.py", line 74, in run
    return asyncio.run(self._run_or_cancel(fn))
  File "/home/ace/miniconda3/envs/lnenv/lib/python3.8/asyncio/runners.py", line 44, in run
    return loop.run_until_complete(main)
  File "/home/ace/miniconda3/envs/lnenv/lib/python3.8/asyncio/base_events.py", line 616, in run_until_complete
    return future.result()
  File "/home/ace/miniconda3/envs/lnenv/lib/python3.8/site-packages/wandb/sdk/lib/asyncio_compat.py", line 98, in _run_or_cancel
    return fn_task.result()
  File "/home/ace/miniconda3/envs/lnenv/lib/python3.8/site-packages/wandb/sdk/mailbox/wait_with_progress.py", line 82, in progress_loop_with_timeout
    return await _wait_handles_async(
  File "/home/ace/miniconda3/envs/lnenv/lib/python3.8/site-packages/wandb/sdk/mailbox/wait_with_progress.py", line 132, in _wait_handles_async
    task_group.start_soon(wait_single(index))
  File "/home/ace/miniconda3/envs/lnenv/lib/python3.8/contextlib.py", line 178, in __aexit__
    await self.gen.__anext__()
  File "/home/ace/miniconda3/envs/lnenv/lib/python3.8/site-packages/wandb/sdk/lib/asyncio_compat.py", line 190, in open_task_group
    await task_group._wait_all()
  File "/home/ace/miniconda3/envs/lnenv/lib/python3.8/site-packages/wandb/sdk/lib/asyncio_compat.py", line 159, in _wait_all
    raise exc
  File "/home/ace/miniconda3/envs/lnenv/lib/python3.8/site-packages/wandb/sdk/mailbox/wait_with_progress.py", line 128, in wait_single
    results[index] = await handle.wait_async(timeout=timeout)
  File "/home/ace/miniconda3/envs/lnenv/lib/python3.8/site-packages/wandb/sdk/mailbox/mailbox_handle.py", line 126, in wait_async
    response = await self._handle.wait_async(timeout=timeout)
  File "/home/ace/miniconda3/envs/lnenv/lib/python3.8/site-packages/wandb/sdk/mailbox/response_handle.py", line 118, in wait_async
    raise TimeoutError(
TimeoutError: Timed out waiting for response on 3h5ztoc3x240

During handling of the above exception, another exception occurred:

Traceback (most recent call last):
  File "/home/ace/miniconda3/envs/lnenv/lib/python3.8/site-packages/wandb/sdk/wandb_init.py", line 1468, in init
    return wi.init(run_settings, run_config)
  File "/home/ace/miniconda3/envs/lnenv/lib/python3.8/site-packages/wandb/sdk/wandb_init.py", line 954, in init
    raise CommError(
wandb.errors.errors.CommError: Run initialization has timed out after 90.0 sec. Please try increasing the timeout with the `init_timeout` setting: `wandb.init(settings=wandb.Settings(init_timeout=120))`.
2025-04-24 21:13:49,961 INFO    MsgRouterThr:17184 [mailbox.py:close():129] Closing mailbox, abandoning 1 handles.
